<?xml version="1.0" encoding="utf-8"?>
<robot
  name="piper"
  xmlns:xacro="http://ros.org/wiki/xacro">
<!-- world -->
  <link name="world"/>
  <joint name="fixed_base_joint" type="fixed">
      <parent link="world"/>
      <child link="base_link"/>
  </joint>
<!-- arm -->
<link
    name="base_link">
    <inertial>
            <origin xyz="-0.00473641164191482 2.56829134630247E-05 0.041451518036016" rpy="0 0 0" />
            <mass value="1.02" />
            <inertia ixx="0.00267433" ixy="-0.00000073" ixz="-0.00017389" iyy="0.00282612" iyz="0.0000004" izz="0.00089624" />
    </inertial>
    <visual>
      <origin
        xyz="0 0 0"
        rpy="0 0 0" />
      <geometry>
        <mesh
          filename="file://$(find piper_description)/meshes/base_link.STL" />
      </geometry>
      <material
        name="">
        <color
          rgba="0.792156862745098 0.819607843137255 0.933333333333333 1" />
      </material>
    </visual>
    <collision>
      <origin
        xyz="0 0 0"
        rpy="0 0 0" />
      <geometry>
        <mesh
          filename="file://$(find piper_description)/meshes/base_link.STL" />
      </geometry>
    </collision>
  </link>
  <link
    name="link1">
    <inertial>
      <origin xyz="0.00032 -0.00041 -0.00348" rpy="0 0 0" />
      <mass value="0.71" />
      <inertia ixx="0.00050027" ixy="0.00000078" ixz="0.00000626" iyy="0.00040879" iyz="0.00000462" izz="0.00045802" />
    </inertial>
    <visual>
      <origin
        xyz="0 0 0"
        rpy="0 0 0" />
      <geometry>
        <mesh
          filename="file://$(find piper_description)/meshes/link1.STL" />
      </geometry>
      <material
        name="">
        <color
          rgba="0.792156862745098 0.819607843137255 0.933333333333333 1" />
      </material>
    </visual>
    <collision>
      <origin
        xyz="0 0 0"
        rpy="0 0 0" />
      <geometry>
        <mesh
          filename="file://$(find piper_description)/meshes/link1.STL" />
      </geometry>
    </collision>
  </link>
  <joint
    name="joint1"
    type="revolute">
    <origin
      xyz="0 0 0.123"
      rpy="0 0 0" />
    <parent
      link="base_link" />
    <child
      link="link1" />
    <axis
      xyz="0 0 1" />
    <limit
      lower="-2.618"
      upper="2.618"
      effort="300"
      velocity="5" />
  </joint>
  <link
    name="link2">
    <inertial>
      <origin xyz="0.21852 -0.00861 0.00126" rpy="0 0 0" />
      <mass value="1.16" />
      <inertia ixx="0.00111915" ixy="0.00182916" ixz="0.00019233" iyy="0.06763251" iyz="0.00000767" izz="0.067559" />
    </inertial>
    <visual>
      <origin
        xyz="0 0 0"
        rpy="0 0 0" />
      <geometry>
        <mesh
          filename="file://$(find piper_description)/meshes/link2.STL" />
      </geometry>
      <material
        name="">
        <color
          rgba="0.792156862745098 0.819607843137255 0.933333333333333 1" />
      </material>
    </visual>
    <collision>
      <origin
        xyz="0 0 0"
        rpy="0 0 0" />
      <geometry>
        <mesh
          filename="file://$(find piper_description)/meshes/link2.STL" />
      </geometry>
    </collision>
  </link>
  <joint
    name="joint2"
    type="revolute">
    <origin
      xyz="0 0 0"
      rpy="1.5708 -0.1359 -3.1416" />
      <!-- rpy="1.5708 -0.10095-0.03490659 -3.1416" /> -->
    <parent
      link="link1" />
    <child
      link="link2" />
    <axis
      xyz="0 0 1" />
    <limit
      lower="0"
      upper="3.14"
      effort="300"
      velocity="5" />
  </joint>
  <link
    name="link3">
    <inertial>
      <origin xyz="-0.01999 -0.14808 -0.00053" rpy="0 0 0" />
      <mass value="0.5" />
      <inertia ixx="0.01347608" ixy="0.00161034" ixz="0.00000066" iyy="0.00046377" iyz="0.00000162" izz="0.01363321" />
    </inertial>
    <visual>
      <origin
        xyz="0 0 0"
        rpy="0 0 0" />
      <geometry>
        <mesh
          filename="file://$(find piper_description)/meshes/link3.STL" />
      </geometry>
      <material
        name="">
        <color
          rgba="0.792156862745098 0.819607843137255 0.933333333333333 1" />
      </material>
    </visual>
    <collision>
      <origin
        xyz="0 0 0"
        rpy="0 0 0" />
      <geometry>
        <mesh
          filename="file://$(find piper_description)/meshes/link3.STL" />
      </geometry>
    </collision>
  </link>
  <joint
    name="joint3"
    type="revolute">
    <origin
      xyz="0.28503 0 0"
      rpy="0 0 -1.7939" />
      <!-- rpy="0 0 -1.759-0.03490659" /> -->
    <parent
      link="link2" />
    <child
      link="link3" />
    <axis
      xyz="0 0 1" />
    <limit
      lower="-2.967"
      upper="0"
      effort="300"
      velocity="5" />
  </joint>
  <link
    name="link4">
    <inertial>
      <origin xyz="0.00013 -0.00076 -0.00394" rpy="0 0 0" />
      <mass value="0.38" />
      <inertia ixx="0.00017844" ixy="0.00000062" ixz="0.00000067" iyy="0.00018914" iyz="0.00000408" izz="0.00014613" />
    </inertial>
    <visual>
      <origin
        xyz="0 0 0"
        rpy="0 0 0" />
      <geometry>
        <mesh
          filename="file://$(find piper_description)/meshes/link4.STL" />
      </geometry>
      <material
        name="">
        <color
          rgba="0.792156862745098 0.819607843137255 0.933333333333333 1" />
      </material>
    </visual>
    <collision>
      <origin
        xyz="0 0 0"
        rpy="0 0 0" />
      <geometry>
        <mesh
          filename="file://$(find piper_description)/meshes/link4.STL" />
      </geometry>
    </collision>
  </link>
  <joint
    name="joint4"
    type="revolute">
    <origin
      xyz="-0.021984 -0.25075 0"
      rpy="1.5708 0 0" />
    <parent
      link="link3" />
    <child
      link="link4" />
    <axis
      xyz="0 0 1" />
    <limit
      lower="-1.745"
      upper="1.745"
      effort="300"
      velocity="5" />
  </joint>
  <link
    name="link5">
    <inertial>
      <origin xyz="0.00018 -0.06104 -0.00227" rpy="0 0 0" />
      <mass value="0.383" />
      <inertia ixx="0.00172318" ixy="0.00000259" ixz="0.00000010" iyy="0.00017936" iyz="0.00000990" izz="0.00171172" />
    </inertial>
    <visual>
      <origin
        xyz="0 0 0"
        rpy="0 0 0" />
      <geometry>
        <mesh
          filename="file://$(find piper_description)/meshes/link5.STL" />
      </geometry>
      <material
        name="">
        <color
          rgba="0.792156862745098 0.819607843137255 0.933333333333333 1" />
      </material>
    </visual>
    <collision>
      <origin
        xyz="0 0 0"
        rpy="0 0 0" />
      <geometry>
        <mesh
          filename="file://$(find piper_description)/meshes/link5.STL" />
      </geometry>
    </collision>
  </link>
  <joint
    name="joint5"
    type="revolute">
    <origin
      xyz="0 0 0"
      rpy="-1.5708 0 0" />
    <parent
      link="link4" />
    <child
      link="link5" />
    <axis
      xyz="0 0 1" />
    <limit
      lower="-1.22"
      upper="1.22"
      effort="300"
      velocity="5" />
  </joint>
  <link
    name="link6">
    <inertial>
      <origin xyz="-0.00003 0.00006 0.04618" rpy="0 0 0" />
      <mass value="0.007" />
      <inertia ixx="0.00152112" ixy="0.00000202" ixz="0.00000261" iyy="0.00138626" iyz="0.00000002" izz="0.00031152" />
    </inertial>
    <visual>
      <origin
        xyz="0 0 0"
        rpy="0 0 0" />
      <geometry>
        <mesh
          filename="file://$(find piper_description)/meshes/link6.STL" />
      </geometry>
      <material
        name="">
        <color
          rgba="0.898039215686275 0.917647058823529 0.929411764705882 1" />
      </material>
    </visual>
    <collision>
      <origin
        xyz="0 0 0"
        rpy="0 0 0" />
      <geometry>
        <mesh
          filename="file://$(find piper_description)/meshes/link6.STL" />
      </geometry>
    </collision>
  </link>
  <joint
    name="joint6"
    type="revolute">
    <origin
      xyz="8.8259E-05 -0.091 0"
      rpy="1.5708 0 0" />
    <parent
      link="link5" />
    <child
      link="link6" />
    <axis
      xyz="0 0 1" />
    <limit
      lower="-2.0944"
      upper="2.0944"
      effort="100"
      velocity="3" />
  </joint>

  <!-- <gazebo reference="base_link">
      <material>Gazebo/Black</material>
      <gravity>true</gravity>
      <selfCollide>false</selfCollide>
  </gazebo>
  <gazebo reference="link1">
      <material>Gazebo/Gray</material>
      <selfCollide>false</selfCollide>
  </gazebo>
  <gazebo reference="link2">
      <material>Gazebo/Red</material>
      <selfCollide>false</selfCollide>
  </gazebo>
  <gazebo reference="link3">
      <material>Gazebo/Blue</material>
  </gazebo>
  <gazebo reference="link4">
      <material>Gazebo/Green</material>
  </gazebo>
  <gazebo reference="link5">
      <material>Gazebo/Yellow</material>
  </gazebo>
  <gazebo reference="link6">
      <material>Gazebo/Orange</material>
  </gazebo>-->

  <ros2_control name="GazeboSystem" type="system">
      <hardware>
          <plugin>gazebo_ros2_control/GazeboSystem</plugin>
      </hardware>
      <joint name="joint1">
          <command_interface name="position"/>
          <state_interface name="position">
              <param name="initial_value">0.0</param>
          </state_interface>
          <state_interface name="velocity"/>
          <state_interface name="effort"/>
      </joint>
      <joint name="joint2">
          <command_interface name="position"/>
          <state_interface name="position">
              <param name="initial_value">0.0</param>
          </state_interface>
          <state_interface name="velocity"/>
          <state_interface name="effort"/>
      </joint>
      <joint name="joint3">
          <command_interface name="position"/>
          <state_interface name="position">
              <param name="initial_value">0.0</param>
          </state_interface>
          <state_interface name="velocity"/>
          <state_interface name="effort"/>
      </joint>
      <joint name="joint4">
          <command_interface name="position"/>
          <state_interface name="position">
              <param name="initial_value">0.0</param>
          </state_interface>
          <state_interface name="velocity"/>
          <state_interface name="effort"/>
      </joint>
      <joint name="joint5">
          <command_interface name="position"/>
          <state_interface name="position">
              <param name="initial_value">0.0</param>
          </state_interface>
          <state_interface name="velocity"/>
          <state_interface name="effort"/>
      </joint>
      <joint name="joint6">
          <command_interface name="position"/>
          <state_interface name="position">
              <param name="initial_value">0.0</param>
          </state_interface>
          <state_interface name="velocity"/>
          <state_interface name="effort"/>
      </joint>
  </ros2_control>

  <!-- ===================== Section 3 additions ===================== -->
  <!-- Wiping pad (tool) rigidly attached to the wrist. The 100x50 mm pad from
       the assignment; thin box so its lower face contacts the surface. -->
  <link name="tool_link">
    <inertial>
      <mass value="0.05"/>
      <origin xyz="0 0 0" rpy="0 0 0"/>
      <inertia ixx="1e-4" ixy="0" ixz="0" iyy="1e-4" iyz="0" izz="1e-4"/>
    </inertial>
    <visual>
      <origin xyz="0 0 0" rpy="0 0 0"/>
      <geometry><box size="0.10 0.05 0.02"/></geometry>
      <material name="pad"><color rgba="0.1 0.6 0.9 0.4"/></material>
    </visual>
    <collision>
      <origin xyz="0 0 0" rpy="0 0 0"/>
      <geometry><box size="0.10 0.05 0.02"/></geometry>
    </collision>
  </link>
  <!-- Fixed joint link6->tool_link. Offset along link6 +z (the approach axis) so
       the pad sits just past the flange. The F/T sensor measures the wrench
       transmitted across THIS joint = the contact wrench on the pad. -->
  <!-- LOCKED revolute (lower=upper=0): keeps tool_link a SEPARATE colliding body
       (a fixed joint lumps it into link6 and the wrist FT can't see the contact),
       and gives us a real joint to put <provideFeedback> on so Gazebo reports the
       contact wrench transmitted through it. This is the friend's design. -->
  <joint name="tool_joint" type="revolute">
    <!-- pad mounted flush at link6 tip: centre 1 cm out so its near face sits on
         link6 (no gap) and its contact face is at 2 cm = tool_len in the planner. -->
    <origin xyz="0 0 0.01" rpy="0 0 0"/>
    <parent link="link6"/>
    <child link="tool_link"/>
    <axis xyz="0 0 1"/>
    <limit lower="0" upper="0" effort="1000" velocity="0"/>
  </joint>

  <!-- Wrist force/torque sensing. Gazebo Classic's gazebo_ros2_control does NOT
       support force_torque sensors as state interfaces ("Conversion of sensor
       type[force_torque] not supported"), and a fixed tool_joint gets lumped
       away, so we measure the reaction wrench on joint6 (a real revolute joint
       that always provides feedback) and publish it with the stock
       gazebo_ros_ft_sensor plugin. The pad (tool_link) lumps into link6 and
       carries the contact. Force is reported in the link6/joint6 frame; the
       controller transforms it to the surface normal. -->
  <gazebo reference="tool_joint">
    <provideFeedback>true</provideFeedback>
    <!-- keep the pad a SEPARATE body (do not lump it into link6), so the F/T
         sensor on tool_joint measures the real contact force between the wrist and
         the pad. Without this the pad lumps into link6 and the sensor reads ~0 even
         when the pad presses the surface (matches griffin_ws's working setup). -->
    <disableFixedJointLumping>true</disableFixedJointLumping>
  </gazebo>
  <gazebo>
    <plugin name="tool_ft_sensor" filename="libgazebo_ros_ft_sensor.so">
      <ros>
        <namespace>/</namespace>
        <remapping>wrench:=wrist_ft</remapping>
      </ros>
      <update_rate>100.0</update_rate>
      <joint_name>tool_joint</joint_name>
      <gaussian_noise>0.0</gaussian_noise>
    </plugin>
  </gazebo>
  <gazebo reference="tool_link">
    <material>Gazebo/BlueLaser</material>
    <mu1>1.0</mu1>
    <mu2>1.0</mu2>
    <!-- Compliant contact so |F| varies smoothly with penetration depth
         (~10 N at ~1 mm), letting the admittance loop regulate to target
         instead of slamming between 0 and >15 N on a rigid surface. -->
    <kp>5000.0</kp>
    <kd>50.0</kd>
    <minDepth>0.001</minDepth>
    <maxVel>0.1</maxVel>
  </gazebo>

<!-- gazebo -->
  <gazebo>
    <plugin name="gazebo_ros2_control" filename="libgazebo_ros2_control.so">
        <parameters> $(find gr_wiping_control)/config/wiping_controllers.yaml </parameters>
        <robot_param_node>robot_state_publisher</robot_param_node>
    </plugin>
  </gazebo>
 
</robot>
